Workbook

Sheet Base
A1: DATE | B1: RETURNS_APPLE | C1: RV_APPLE
A2: 37623 | B2: =_xlfn.XLOOKUP(A2, Dados!$C:$C, Dados!$D:$D, "") -> 3.2798344 | C2: 8.3081986
A3: 37624 | B3: =_xlfn.XLOOKUP(A3, Dados!$C:$C, Dados!$D:$D, "") -> 0.6756718 | C3: 6.5681596
A4: 37627 | B4: =_xlfn.XLOOKUP(A4, Dados!$C:$C, Dados!$D:$D, "") -> 0 | C4: 7.3444175
A5: 37628 | B5: =_xlfn.XLOOKUP(A5, Dados!$C:$C, Dados!$D:$D, "") -> -0.33556536 | C5: 10.013332
A6: 37629 | B6: =_xlfn.XLOOKUP(A6, Dados!$C:$C, Dados!$D:$D, "") -> -2.0202033 | C6: 6.0982123
A7: 37630 | B7: =_xlfn.XLOOKUP(A7, Dados!$C:$C, Dados!$D:$D, "") -> 0.89347157 | C7: 5.5478247
A8: 37631 | B8: =_xlfn.XLOOKUP(A8, Dados!$C:$C, Dados!$D:$D, "") -> 0.2724793 | C8: 7.4339731
A9: 37634 | B9: =_xlfn.XLOOKUP(A9, Dados!$C:$C, Dados!$D:$D, "") -> -0.61141407 | C9: 6.9825713
A10: 37635 | B10: =_xlfn.XLOOKUP(A10, Dados!$C:$C, Dados!$D:$D, "") -> -0.13670853 | C10: 5.025234
A11: 37636 | B11: =_xlfn.XLOOKUP(A11, Dados!$C:$C, Dados!$D:$D, "") -> -1.2320284 | C11: 5.5881082
A12: 37637 | B12: =_xlfn.XLOOKUP(A12, Dados!$C:$C, Dados!$D:$D, "") -> 1.3166984 | C12: 7.5931401
A13: 37638 | B13: =_xlfn.XLOOKUP(A13, Dados!$C:$C, Dados!$D:$D, "") -> -3.5567682 | C13: 5.6256218
... A5347: 45379 | B5347: =_xlfn.XLOOKUP(A5347, Dados!$C:$C, Dados!$D:$D, "") -> -1.0559114 | C5347: 0.67643184

Sheet Dados
A1: RV_DATE | B1: RV_APPLE | C1: RETURNS_DATE | D1: RETURNS_APPLE
A2: 02-Jan-2003 | B2: 8.3081986 | C2: 34470 | D2: -
A3: 03-Jan-2003 | B3: 6.5681596 | C3: 34471 | D3: -
A4: 06-Jan-2003 | B4: 7.3444175 | C4: 34472 | D4: -
A5: 07-Jan-2003 | B5: 10.013332 | C5: 34473 | D5: -
A6: 08-Jan-2003 | B6: 6.0982123 | C6: 34474 | D6: -
A7: 09-Jan-2003 | B7: 5.5478247 | C7: 34477 | D7: -
A8: 10-Jan-2003 | B8: 7.4339731 | C8: 34478 | D8: -
A9: 13-Jan-2003 | B9: 6.9825713 | C9: 34479 | D9: -
A10: 14-Jan-2003 | B10: 5.025234 | C10: 34480 | D10: -
A11: 15-Jan-2003 | B11: 5.5881082 | C11: 34481 | D11: -
A12: 16-Jan-2003 | B12: 7.5931401 | C12: 34484 | D12: -
A13: 17-Jan-2003 | B13: 5.6256218 | C13: 34485 | D13: -
... A427: 10-Sep-2004 | B427: 3.5706104 | C427: 35065 | D427: -
A428: 13-Sep-2004 | B428: 2.7631227 | C428: 35066 | D428: 0.78431373
A429: 14-Sep-2004 | B429: 3.1730312 | C429: 35067 | D429: 0
A430: 15-Sep-2004 | B430: 2.5983319 | C430: 35068 | D430: -1.7509728
A431: 16-Sep-2004 | B431: 4.7489612 | C431: 35069 | D431: 8.5148515
A432: 17-Sep-2004 | B432: 3.3207761 | C432: 35072 | D432: 1.0948905
A433: 20-Sep-2004 | B433: 2.4761915 | C433: 35073 | D433: -5.4151625
A434: 21-Sep-2004 | B434: 3.5536363 | C434: 35074 | D434: 4.5801527
A435: 22-Sep-2004 | B435: 3.2328899 | C435: 35075 | D435: 2.189781
A436: 23-Sep-2004 | B436: 2.4836025 | C436: 35076 | D436: -3.2142857
A437: 24-Sep-2004 | B437: 4.2788252 | C437: 35079 | D437: 0.73800738
A438: 27-Sep-2004 | B438: 3.2912455 | C438: 35080 | D438: 1.2820513
A439: 28-Sep-2004 | B439: 2.5506375 | C439: 35081 | D439: -1.6274864
... A461: 28-Oct-2004 | B461: 3.6831329 | C461: 35111 | D461: -1.7857143
A462: 29-Oct-2004 | B462: 3.5273043 | C462: 35114 | D462: -
A463: 01-Nov-2004 | B463: 4.1352684 | C463: 35115 | D463: 5.4545455
A464: 02-Nov-2004 | B464: 2.7157207 | C464: 35116 | D464: 2.1551724
A465: 03-Nov-2004 | B465: 4.434259 | C465: 35117 | D465: 0.84388186
A466: 04-Nov-2004 | B466: 4.8305706 | C466: 35118 | D466: 0
A467: 05-Nov-2004 | B467: 7.7895509 | C467: 35121 | D467: -1.2552301
A468: 08-Nov-2004 | B468: 4.320591 | C468: 35122 | D468: -2.9661017
A469: 09-Nov-2004 | B469: 3.0371 | C469: 35123 | D469: -3.0567686
A470: 10-Nov-2004 | B470: 3.2207229 | C470: 35124 | D470: -0.9009009
A471: 11-Nov-2004 | B471: 3.3398079 | C471: 35125 | D471: -2.2727273
A472: 12-Nov-2004 | B472: 2.4612291 | C472: 35128 | D472: -2.3255814
A473: 15-Nov-2004 | B473: 2.5134873 | C473: 35129 | D473: 1.4285714
A474: 16-Nov-2004 | B474: 1.5567891 | C474: 35130 | D474: -1.6431925
...
